<?xml version="1.0" encoding="UTF-8"?>

<robot xmlns:xacro="http://www.ros.org/wiki/xacro" name="leg">


  <xacro:property name="pi" value="3.1415926535897931"/>


  <xacro:macro name="leg" params="name">


    <link name="${name}_leg_base_link">

      <visual>
        <origin xyz="0.036 0 0" rpy="0 0 ${-pi/2}"/>
        <geometry>
          <mesh filename="package://hexapod_description/meshes/AX12.dae" scale="0.001 0.001 0.001"/>
        </geometry>
      </visual>

    </link>


    <joint name="${name}_leg_joint_0" type="continuous">
      <parent link="${name}_leg_base_link"/>
      <child link="${name}_leg_link_0"/>
      <origin xyz="0.036 0 0" rpy="0 0 0"/>
      <axis xyz="0 0 1"/>
    </joint>


    <link name="${name}_leg_link_0">

      <visual>
        <origin xyz="0 0 0" rpy="0 ${pi/2} 0"/>
        <geometry>
          <mesh filename="package://hexapod_description/meshes/F2.dae" scale="0.001 0.001 0.001"/>
        </geometry>
      </visual>

    </link>


  </xacro:macro>

</robot>
