<?xml version="1.0" encoding="UTF-8"?>

<robot xmlns:xacro="http://www.ros.org/wiki/xacro" name="leg">


  <xacro:property name="pi" value="3.1415926535897931"/>


  <xacro:macro name="leg" params="name">


    <link name="${name}_leg_base_link">

      <visual>
        <origin xyz="0.036 0 0" rpy="0 0 ${-pi/2}"/>
        <geometry>
          <mesh filename="package://hexapod_description/meshes/AX12.dae" scale="0.001 0.001 0.001"/>
        </geometry>
      </visual>

    </link>

    <!-- TODO: change ALL joints to revolute and add limits! -->
    <joint name="${name}_leg_joint_0" type="continuous">
      <parent link="${name}_leg_base_link"/>
      <child link="${name}_leg_link_0"/>
      <origin xyz="0.036 0 0" rpy="0 0 0"/>
      <axis xyz="0 0 1"/>
    </joint>


    <link name="${name}_leg_link_0">

      <visual>
        <origin xyz="0 0 0" rpy="0 ${pi/2} 0"/>
        <geometry>
          <mesh filename="package://hexapod_description/meshes/F2.dae" scale="0.001 0.001 0.001"/>
        </geometry>
      </visual>

      <visual>
        <origin xyz="0.049 0 -0.0145" rpy="${pi/2} 0 ${-pi/2}"/>
        <geometry>
          <mesh filename="package://hexapod_description/meshes/F1.dae" scale="0.001 0.001 0.001"/>
        </geometry>
      </visual>

    </link>

    <joint name="${name}_leg_joint_1" type="continuous">
      <parent link="${name}_leg_link_0"/>
      <child link="${name}_leg_link_1"/>
      <origin xyz="0.049 0 -0.0145" rpy="0 0 0"/>
      <axis xyz="0 1 0"/>
    </joint>

    <link name="${name}_leg_link_1">

      <visual>
        <origin xyz="0 0 0" rpy="${pi/2} ${-pi/2x} 0"/>
        <geometry>
          <mesh filename="package://hexapod_description/meshes/AX12.dae" scale="0.001 0.001 0.001"/>
        </geometry>
      </visual>

      <visual>
        <origin xyz="0.0415 0 0" rpy="0 ${-pi/2} ${pi/2x}"/>
        <geometry>
          <mesh filename="package://hexapod_description/meshes/F3.dae" scale="0.001 0.001 0.001"/>
        </geometry>
      </visual>

      <visual>
        <origin xyz="0.0415 0 0" rpy="0 ${-pi/2} ${-pi/2x}"/>
        <geometry>
          <mesh filename="package://hexapod_description/meshes/F3.dae" scale="0.001 0.001 0.001"/>
        </geometry>
      </visual>

      <visual>
        <origin xyz="0.0605 0 -0.0225" rpy="${-pi/2} 0 ${pi}"/>
        <geometry>
          <mesh filename="package://hexapod_description/meshes/AX12.dae" scale="0.001 0.001 0.001"/>
        </geometry>
      </visual>

    </link>

    <joint name="${name}_leg_joint_2" type="continuous">
      <parent link="${name}_leg_link_1"/>
      <child link="${name}_leg_link_2"/>
      <origin xyz="0.0605 0 -0.0225" rpy="0 0 0"/>
      <axis xyz="0 -1 0"/>
    </joint>

    <link name="${name}_leg_link_2">

      <visual>
        <origin xyz="0 0 0" rpy="${pi} 0 ${pi/2x}"/>
        <geometry>
          <mesh filename="package://hexapod_description/meshes/F4.dae" scale="0.001 0.001 0.001"/>
        </geometry>
      </visual>

      <visual>
        <origin xyz="0.0135 0 -0.055" rpy="${pi/2} ${-pi/2} 0"/>
        <geometry>
          <mesh filename="package://hexapod_description/meshes/F6.dae" scale="0.001 0.001 0.001"/>
        </geometry>
      </visual>

    </link>

  </xacro:macro>

</robot>
